Traceback (most recent call last):
  File "/opt/homebrew/lib/python3.11/site-packages/jupyter_cache/executors/utils.py", line 58, in single_nb_execution
    executenb(
  File "/Users/tollef/Library/Python/3.11/lib/python/site-packages/nbclient/client.py", line 1265, in execute
    return NotebookClient(nb=nb, resources=resources, km=km, **kwargs).execute()
           ^^^^^^^^^^^^^^^^^^^^^^^^^^^^^^^^^^^^^^^^^^^^^^^^^^^^^^^^^^^^^^^^^^^^^
  File "/Users/tollef/Library/Python/3.11/lib/python/site-packages/jupyter_core/utils/__init__.py", line 160, in wrapped
    return loop.run_until_complete(inner)
           ^^^^^^^^^^^^^^^^^^^^^^^^^^^^^^
  File "/opt/homebrew/Cellar/python@3.11/3.11.10/Frameworks/Python.framework/Versions/3.11/lib/python3.11/asyncio/base_events.py", line 654, in run_until_complete
    return future.result()
           ^^^^^^^^^^^^^^^
  File "/Users/tollef/Library/Python/3.11/lib/python/site-packages/nbclient/client.py", line 703, in async_execute
    await self.async_execute_cell(
  File "/Users/tollef/Library/Python/3.11/lib/python/site-packages/nbclient/client.py", line 1021, in async_execute_cell
    await self._check_raise_for_error(cell, cell_index, exec_reply)
  File "/Users/tollef/Library/Python/3.11/lib/python/site-packages/nbclient/client.py", line 915, in _check_raise_for_error
    raise CellExecutionError.from_cell_and_msg(cell, exec_reply_content)
nbclient.exceptions.CellExecutionError: An error occurred while executing the following cell:
------------------
from selenium import webdriver
from selenium.webdriver.common.by import By
from selenium.webdriver.common.keys import Keys
from selenium.webdriver.chrome.service import Service as ChromeService
from webdriver_manager.chrome import ChromeDriverManager
from bs4 import BeautifulSoup
import time

driver = webdriver.Chrome()
------------------

[0;31m---------------------------------------------------------------------------[0m
[0;31mSeleniumManagerException[0m                  Traceback (most recent call last)
File [0;32m/opt/homebrew/lib/python3.11/site-packages/selenium/webdriver/common/service.py:97[0m, in [0;36mService.start[0;34m(self)[0m
[1;32m     96[0m [38;5;28;01mtry[39;00m:
[0;32m---> 97[0m     path [38;5;241m=[39m [43mSeleniumManager[49m[43m([49m[43m)[49m[38;5;241;43m.[39;49m[43mdriver_location[49m[43m([49m[43mbrowser[49m[43m)[49m
[1;32m     98[0m [38;5;28;01mexcept[39;00m WebDriverException [38;5;28;01mas[39;00m new_err:

File [0;32m/opt/homebrew/lib/python3.11/site-packages/selenium/webdriver/common/selenium_manager.py:74[0m, in [0;36mSeleniumManager.driver_location[0;34m(self, browser)[0m
[1;32m     73[0m binary, flag, browser [38;5;241m=[39m [38;5;28mstr[39m([38;5;28mself[39m[38;5;241m.[39mget_binary()), [38;5;124m"[39m[38;5;124m--browser[39m[38;5;124m"[39m, browser
[0;32m---> 74[0m result [38;5;241m=[39m [38;5;28;43mself[39;49m[38;5;241;43m.[39;49m[43mrun[49m[43m([49m[43m([49m[43mbinary[49m[43m,[49m[43m [49m[43mflag[49m[43m,[49m[43m [49m[43mbrowser[49m[43m)[49m[43m)[49m
[1;32m     75[0m executable [38;5;241m=[39m result[38;5;241m.[39msplit([38;5;124m"[39m[38;5;130;01m\t[39;00m[38;5;124m"[39m)[[38;5;241m-[39m[38;5;241m1[39m][38;5;241m.[39mstrip()

File [0;32m/opt/homebrew/lib/python3.11/site-packages/selenium/webdriver/common/selenium_manager.py:93[0m, in [0;36mSeleniumManager.run[0;34m(args)[0m
[1;32m     92[0m [38;5;28;01mif[39;00m completed_proc[38;5;241m.[39mreturncode:
[0;32m---> 93[0m     [38;5;28;01mraise[39;00m SeleniumManagerException([38;5;124mf[39m[38;5;124m"[39m[38;5;124mSelenium manager failed for: [39m[38;5;132;01m{[39;00mcommand[38;5;132;01m}[39;00m[38;5;124m. [39m[38;5;132;01m{[39;00mstderr[38;5;132;01m}[39;00m[38;5;124m"[39m)
[1;32m     94[0m [38;5;28;01melse[39;00m:
[1;32m     95[0m     [38;5;66;03m# selenium manager exited 0 successfully, parse the executable path from stdout.[39;00m

[0;31mSeleniumManagerException[0m: Message: Selenium manager failed for: /opt/homebrew/lib/python3.11/site-packages/selenium/webdriver/common/macos/selenium-manager --browser chrome. 


During handling of the above exception, another exception occurred:

[0;31mWebDriverException[0m                        Traceback (most recent call last)
Cell [0;32mIn[3], line 9[0m
[1;32m      6[0m [38;5;28;01mfrom[39;00m[38;5;250m [39m[38;5;21;01mbs4[39;00m[38;5;250m [39m[38;5;28;01mimport[39;00m BeautifulSoup
[1;32m      7[0m [38;5;28;01mimport[39;00m[38;5;250m [39m[38;5;21;01mtime[39;00m
[0;32m----> 9[0m driver [38;5;241m=[39m [43mwebdriver[49m[38;5;241;43m.[39;49m[43mChrome[49m[43m([49m[43m)[49m

File [0;32m/opt/homebrew/lib/python3.11/site-packages/selenium/webdriver/chrome/webdriver.py:81[0m, in [0;36mWebDriver.__init__[0;34m(self, executable_path, port, options, service_args, desired_capabilities, service_log_path, chrome_options, service, keep_alive)[0m
[1;32m     78[0m [38;5;28;01mif[39;00m [38;5;129;01mnot[39;00m service:
[1;32m     79[0m     service [38;5;241m=[39m Service(executable_path, port, service_args, service_log_path)
[0;32m---> 81[0m [38;5;28;43msuper[39;49m[43m([49m[43m)[49m[38;5;241;43m.[39;49m[38;5;21;43m__init__[39;49m[43m([49m
[1;32m     82[0m [43m    [49m[43mDesiredCapabilities[49m[38;5;241;43m.[39;49m[43mCHROME[49m[43m[[49m[38;5;124;43m"[39;49m[38;5;124;43mbrowserName[39;49m[38;5;124;43m"[39;49m[43m][49m[43m,[49m
[1;32m     83[0m [43m    [49m[38;5;124;43m"[39;49m[38;5;124;43mgoog[39;49m[38;5;124;43m"[39;49m[43m,[49m
[1;32m     84[0m [43m    [49m[43mport[49m[43m,[49m
[1;32m     85[0m [43m    [49m[43moptions[49m[43m,[49m
[1;32m     86[0m [43m    [49m[43mservice_args[49m[43m,[49m
[1;32m     87[0m [43m    [49m[43mdesired_capabilities[49m[43m,[49m
[1;32m     88[0m [43m    [49m[43mservice_log_path[49m[43m,[49m
[1;32m     89[0m [43m    [49m[43mservice[49m[43m,[49m
[1;32m     90[0m [43m    [49m[43mkeep_alive[49m[43m,[49m
[1;32m     91[0m [43m[49m[43m)[49m

File [0;32m/opt/homebrew/lib/python3.11/site-packages/selenium/webdriver/chromium/webdriver.py:103[0m, in [0;36mChromiumDriver.__init__[0;34m(self, browser_name, vendor_prefix, port, options, service_args, desired_capabilities, service_log_path, service, keep_alive)[0m
[1;32m    100[0m     [38;5;28;01mraise[39;00m [38;5;167;01mAttributeError[39;00m([38;5;124m"[39m[38;5;124mservice cannot be None[39m[38;5;124m"[39m)
[1;32m    102[0m [38;5;28mself[39m[38;5;241m.[39mservice [38;5;241m=[39m service
[0;32m--> 103[0m [38;5;28;43mself[39;49m[38;5;241;43m.[39;49m[43mservice[49m[38;5;241;43m.[39;49m[43mstart[49m[43m([49m[43m)[49m
[1;32m    105[0m [38;5;28;01mtry[39;00m:
[1;32m    106[0m     [38;5;28msuper[39m()[38;5;241m.[39m[38;5;21m__init__[39m(
[1;32m    107[0m         command_executor[38;5;241m=[39mChromiumRemoteConnection(
[1;32m    108[0m             remote_server_addr[38;5;241m=[39m[38;5;28mself[39m[38;5;241m.[39mservice[38;5;241m.[39mservice_url,
[0;32m   (...)[0m
[1;32m    114[0m         options[38;5;241m=[39moptions,
[1;32m    115[0m     )

File [0;32m/opt/homebrew/lib/python3.11/site-packages/selenium/webdriver/common/service.py:100[0m, in [0;36mService.start[0;34m(self)[0m
[1;32m     98[0m         [38;5;28;01mexcept[39;00m WebDriverException [38;5;28;01mas[39;00m new_err:
[1;32m     99[0m             logger[38;5;241m.[39mdebug([38;5;124m"[39m[38;5;124mUnable to obtain driver using Selenium Manager: [39m[38;5;124m"[39m [38;5;241m+[39m new_err[38;5;241m.[39mmsg)
[0;32m--> 100[0m             [38;5;28;01mraise[39;00m err
[1;32m    102[0m         [38;5;28mself[39m[38;5;241m.[39m_start_process(path)
[1;32m    104[0m count [38;5;241m=[39m [38;5;241m0[39m

File [0;32m/opt/homebrew/lib/python3.11/site-packages/selenium/webdriver/common/service.py:90[0m, in [0;36mService.start[0;34m(self)[0m
[1;32m     82[0m [38;5;250m[39m[38;5;124;03m"""[39;00m
[1;32m     83[0m [38;5;124;03mStarts the Service.[39;00m
[1;32m     84[0m 
[0;32m   (...)[0m
[1;32m     87[0m [38;5;124;03m   or when it can't connect to the service[39;00m
[1;32m     88[0m [38;5;124;03m"""[39;00m
[1;32m     89[0m [38;5;28;01mtry[39;00m:
[0;32m---> 90[0m     [38;5;28;43mself[39;49m[38;5;241;43m.[39;49m[43m_start_process[49m[43m([49m[38;5;28;43mself[39;49m[38;5;241;43m.[39;49m[43mpath[49m[43m)[49m
[1;32m     91[0m [38;5;28;01mexcept[39;00m WebDriverException [38;5;28;01mas[39;00m err:
[1;32m     92[0m     [38;5;28;01mif[39;00m [38;5;124m"[39m[38;5;124mexecutable needs to be in PATH[39m[38;5;124m"[39m [38;5;129;01min[39;00m err[38;5;241m.[39mmsg:

File [0;32m/opt/homebrew/lib/python3.11/site-packages/selenium/webdriver/common/service.py:213[0m, in [0;36mService._start_process[0;34m(self, path)[0m
[1;32m    211[0m [38;5;28;01mexcept[39;00m [38;5;167;01mOSError[39;00m [38;5;28;01mas[39;00m err:
[1;32m    212[0m     [38;5;28;01mif[39;00m err[38;5;241m.[39merrno [38;5;241m==[39m errno[38;5;241m.[39mENOENT:
[0;32m--> 213[0m         [38;5;28;01mraise[39;00m WebDriverException(
[1;32m    214[0m             [38;5;124mf[39m[38;5;124m"[39m[38;5;124m'[39m[38;5;132;01m{[39;00mos[38;5;241m.[39mpath[38;5;241m.[39mbasename([38;5;28mself[39m[38;5;241m.[39mpath)[38;5;132;01m}[39;00m[38;5;124m'[39m[38;5;124m executable needs to be in PATH. [39m[38;5;132;01m{[39;00m[38;5;28mself[39m[38;5;241m.[39mstart_error_message[38;5;132;01m}[39;00m[38;5;124m"[39m
[1;32m    215[0m         )
[1;32m    216[0m     [38;5;28;01melif[39;00m err[38;5;241m.[39merrno [38;5;241m==[39m errno[38;5;241m.[39mEACCES:
[1;32m    217[0m         [38;5;28;01mraise[39;00m WebDriverException(
[1;32m    218[0m             [38;5;124mf[39m[38;5;124m"[39m[38;5;124m'[39m[38;5;132;01m{[39;00mos[38;5;241m.[39mpath[38;5;241m.[39mbasename([38;5;28mself[39m[38;5;241m.[39mpath)[38;5;132;01m}[39;00m[38;5;124m'[39m[38;5;124m executable may have wrong permissions. [39m[38;5;132;01m{[39;00m[38;5;28mself[39m[38;5;241m.[39mstart_error_message[38;5;132;01m}[39;00m[38;5;124m"[39m
[1;32m    219[0m         )

[0;31mWebDriverException[0m: Message: 'chromedriver' executable needs to be in PATH. Please see https://chromedriver.chromium.org/home

WebDriverException: Message: 'chromedriver' executable needs to be in PATH. Please see https://chromedriver.chromium.org/home


